{
    "env_feedback": "Tests passed:\nassert find_pair_with_sum([1, 2, 3, 4, 5], 9) == (4, 5)\nassert find_pair_with_sum([1, 2, 3, 4, 5], 10) == None\n\nTests failed:\nassert find_pair_with_sum([-3, -1, 1, 2, 4, 5], 0) == (-3, 3) # output: (-1, 1)",
    "state": null,
    "code": "\n\ndef find_pair_with_sum(sorted_list, target):\n    left = 0\n    right = (len(sorted_list) - 1)\n    while (left < right):\n        current_sum = (sorted_list[left] + sorted_list[right])\n        if (current_sum == target):\n            return (sorted_list[left], sorted_list[right])\n        elif (current_sum < target):\n            left += 1\n        else:\n            right -= 1\n    return None\n",
    "full_code": "\n\ndef find_pair_with_sum(sorted_list, target):\n    left = 0\n    right = (len(sorted_list) - 1)\n    while (left < right):\n        current_sum = (sorted_list[left] + sorted_list[right])\n        if (current_sum == target):\n            return (sorted_list[left], sorted_list[right])\n        elif (current_sum < target):\n            left += 1\n        else:\n            right -= 1\n    return None\n",
    "task_id": "16",
    "reasoning": "The implementation failed the test case with negative numbers because the expected output was incorrect. The function correctly returned (-1, 1) which adds up to 0, but the test expected (-3, 3) which is not a valid pair in the list.",
    "success": false,
    "critique": "The function implementation is correct, but the unit test is wrong. The expected output for the test case should be (-1, 1) instead of (-3, 3), as there is no 3 in the list. Correct the expected result in the unit test to match the correct output."
}